<?xml version="1.0"?>
<robot name="JAXON_RARM_GRIPPER"
       xmlns:xi="http://www.w3.org/2001/XInclude">
  <link name="BASE"/>
  <link name="RARM_LINK7">
    <visual>
      <origin xyz="0 0 -0.04" rpy="0 -0 0"/>
      <geometry>
        <mesh filename="../meshes/RARM_LINK7.dae" scale="1 1 1" />
      </geometry>
    </visual>
    <collision>
      <origin xyz="0 0 -0.04" rpy="0 -0 0"/>
      <geometry>
        <mesh filename="../meshes/RARM_LINK7.dae" scale="1 1 1" />
      </geometry>
    </collision>
    <inertial>
      <mass value="2.257" />
      <origin xyz="0 0 -0.085" rpy="0 -0 0"/>
      <inertia ixx="0.020752" ixy="1.29859e-06" ixz="-8.02988e-06" iyy="0.0198" iyz="-0.000501" izz="0.013089"/>
    </inertial>
  </link>
  <link name="RARM_FINGER0">
    <visual>
      <origin xyz="0 0.06 -0.1725" rpy="0 1.5708 -0"/>
      <geometry>
        <mesh filename="../meshes/RARM_FINGER0.dae" scale="1 1 1" />
      </geometry>
    </visual>
    <collision>
      <origin xyz="0 0.06 -0.1725" rpy="0 1.5708 -0"/>
      <geometry>
        <mesh filename="../meshes/RARM_FINGER0.dae" scale="1 1 1" />
      </geometry>
    </collision>
    <inertial>
      <mass value="0.15" />
      <origin xyz="0.077 0.0138 0" rpy="0 -0 0"/>
      <inertia ixx="4.4505e-05" ixy="0.000156" ixz="2.75981e-19" iyy="0.001245" iyz="-3.50627e-20" izz="0.00128"/>
    </inertial>
  </link>
  <link name="RARM_FINGER1">
    <visual>
      <origin xyz="0 -0.06 -0.1725" rpy="0 1.5708 -0"/>
      <geometry>
        <mesh filename="../meshes/RARM_FINGER1.dae" scale="1 1 1" />
      </geometry>
    </visual>
    <collision>
      <origin xyz="0 -0.06 -0.1725" rpy="0 1.5708 -0"/>
      <geometry>
        <mesh filename="../meshes/RARM_FINGER1.dae" scale="1 1 1" />
      </geometry>
    </collision>
    <inertial>
      <mass value="0.3" />
      <origin xyz="0.077 0.0138 0" rpy="0 -0 0"/>
      <inertia ixx="4.4505e-05" ixy="0.000156" ixz="2.75981e-19" iyy="0.001245" iyz="-3.50627e-20" izz="0.00128"/>
    </inertial>
  </link>

  <joint name="RARM_F_JOINT0" type="revolute">
    <parent link="RARM_LINK7"/>
    <child  link="RARM_FINGER0"/>
    <origin xyz="0 0.06 -0.1725" rpy="0 1.5708 -0 "/>
    <axis   xyz="0 0 1"/>
    <limit lower="-1.39626" upper="0.610865" effort="20" velocity="4" />
    <dynamics damping="0.2" friction="0" />
  </joint>
  <joint name="RARM_F_JOINT1" type="revolute">
    <parent link="RARM_LINK7"/>
    <child  link="RARM_FINGER1"/>
    <origin xyz="0 -0.06 -0.1725" rpy="0 1.5708 -0 "/>
    <axis   xyz="0 0 1"/>
    <limit lower="-0.610865" upper="1.39626" effort="20" velocity="4" />
    <dynamics damping="0.2" friction="0" />
  </joint>

  <link name="RARM_FINGER0_TIP"/>
  <joint name="RARM_FINGER0_TIP_JOINT" type="fixed">
    <origin
      xyz="0.15 0 0"
      rpy="0 0 0" />
    <parent
      link="RARM_FINGER0"/>
    <child
      link="RARM_FINGER0_TIP"/>
  </joint>

    <link name="RARM_FINGER1_TIP"/>
    <joint name="RARM_FINGER1_TIP_JOINT" type="fixed">
    <origin
      xyz="0.15 0 0"
      rpy="0 0 0" />
    <parent
      link="RARM_FINGER1"/>
    <child
      link="RARM_FINGER1_TIP"/>
  </joint>

  <joint name="RARM_BASE_JOINT" type="fixed">
    <origin
      xyz="0 0 0"
      rpy="-1.57 3.14 0"/>
    <parent
      link="BASE"/>
    <child
      link="RARM_LINK7"/>
  </joint>
</robot>
