<?xml version="1.0"?>
<robot name="JAXON_LARM_GRIPPER">
  <link name="BASE"/>
  <link name="LARM_LINK7">
    <visual>
      <origin xyz="0 0 -0.04" rpy="0 -0 0"/>
      <geometry>
        <mesh filename="../meshes/LARM_LINK7.dae" scale="1 1 1" />
      </geometry>
    </visual>
    <collision>
      <origin xyz="0 0 -0.04" rpy="0 -0 0"/>
      <geometry>
        <mesh filename="../meshes/LARM_LINK7.dae" scale="1 1 1" />
      </geometry>
    </collision>
    <inertial>
      <mass value="2.257" />
      <origin xyz="0 0 -0.085" rpy="0 -0 0"/>
      <inertia ixx="0.020752" ixy="-1.29859e-06" ixz="8.02988e-06" iyy="0.0198" iyz="0.000501" izz="0.013089"/>
    </inertial>
  </link>
  <link name="LARM_FINGER0">
    <visual>
      <origin xyz="0 -0.06 -0.1725" rpy="0 1.5708 -3.14159"/>
      <geometry>
        <mesh filename="../meshes/LARM_FINGER0.dae" scale="1 1 1" />
      </geometry>
    </visual>
    <collision>
      <origin xyz="0 -0.06 -0.1725" rpy="0 1.5708 -3.14159"/>
      <geometry>
        <mesh filename="../meshes/LARM_FINGER0.dae" scale="1 1 1" />
      </geometry>
    </collision>
    <inertial>
      <mass value="0.15" />
      <origin xyz="0.077 0.0138 3.38271e-17" rpy="0 -0 0"/>
      <inertia ixx="4.4505e-05" ixy="0.000156" ixz="1.07138e-21" iyy="0.001245" iyz="-3.47216e-22" izz="0.00128"/>
    </inertial>
  </link>
  <link name="LARM_FINGER1">
    <visual>
      <origin xyz="0 0.06 -0.1725" rpy="0 1.5708 -3.14159"/>
      <geometry>
        <mesh filename="../meshes/LARM_FINGER1.dae" scale="1 1 1" />
      </geometry>
    </visual>
    <collision>
      <origin xyz="0 0.06 -0.1725" rpy="0 1.5708 -3.14159"/>
      <geometry>
        <mesh filename="../meshes/LARM_FINGER1.dae" scale="1 1 1" />
      </geometry>
    </collision>
    <inertial>
      <mass value="0.3" />
      <origin xyz="0.077 0.0138 3.38271e-17" rpy="0 -0 0"/>
      <inertia ixx="4.4505e-05" ixy="0.000156" ixz="1.07138e-21" iyy="0.001245" iyz="-3.47216e-22" izz="0.00128"/>
    </inertial>
  </link>


  <joint name="LARM_F_JOINT0" type="revolute">
    <parent link="LARM_LINK7"/>
    <child  link="LARM_FINGER0"/>
    <origin xyz="0 -0.06 -0.1725" rpy="0 1.5708 -3.14159 "/>
    <axis   xyz="0 0 1"/>
    <limit lower="-1.39626" upper="0.610865" effort="20" velocity="4" />
    <dynamics damping="0.2" friction="0" />
  </joint>
  <joint name="LARM_F_JOINT1" type="revolute">
    <parent link="LARM_LINK7"/>
    <child  link="LARM_FINGER1"/>
    <origin xyz="0 0.06 -0.1725" rpy="0 1.5708 -3.14159 "/>
    <axis   xyz="0 0 1"/>
    <limit lower="-0.610865" upper="1.39626" effort="20" velocity="4" />
    <dynamics damping="0.2" friction="0" />
  </joint>

  <link name="LARM_FINGER0_TIP"/>
  <joint name="LARM_FINGER0_TIP_JOINT" type="fixed">
    <origin
      xyz="0.15 0 0"
      rpy="0 0 0" />
    <parent
      link="LARM_FINGER0"/>
    <child
      link="LARM_FINGER0_TIP"/>
  </joint>

    <link name="LARM_FINGER1_TIP"/>
    <joint name="LARM_FINGER1_TIP_JOINT" type="fixed">
    <origin
      xyz="0.15 0 0"
      rpy="0 0 0" />
    <parent
      link="LARM_FINGER1"/>
    <child
      link="LARM_FINGER1_TIP"/>
  </joint>

  <joint name="LARM_BASE_JOINT" type="fixed">
    <origin
      xyz="0 0 0"
      rpy="-1.57 -1.57 0"/>
    <parent
      link="BASE"/>
    <child
      link="LARM_LINK7"/>
  </joint>
</robot>
