<?xml version="1.0" ?>
<!-- =================================================================================== -->
<!-- |    This document was autogenerated by xacro from /home/ros/Desktop/catkin_ws/src/val_description/model/robots/forearm_right.xacro | -->
<!-- |    EDITING THIS FILE BY HAND IS NOT RECOMMENDED                                 | -->
<!-- =================================================================================== -->
<robot name="valkyrie" xmlns:xacro="http://www.ros.org/wiki/xacro">
  <!--Yaw-->
  <!--pitch-->
  <!--roll-->
  <!-- Pulley-1 diameter = 0.01707m -->
  <!-- Pulley-2 diameter = 0.0127m -->
  <!-- Pulley-3 diameter = 0.01016 -->
  <!-- Pulley-1 diameter = 0.01707m -->
  <!-- Pulley-2 diameter = 0.0127m -->
  <!-- Pulley-3 diameter = 0.01016 -->
  <!-- Pulley-1 diameter = 0.01707m -->
  <!-- Pulley-2 diameter = 0.0127m -->
  <!-- Pulley-3 diameter = 0.01016 -->
  <!-- Pulley-1 diameter = 0.01707m -->
  <!-- Pulley-2 diameter = 0.0127m -->
  <!-- Pulley-3 diameter = 0.01016 -->
  <!-- Arm include -->
  <link name="base"/>
  <link name="rightPalm">
    <inertial>
      <mass value="0.712"/>
      <origin rpy="0 0 0" xyz="0.002954 -0.052034 -0.000236"/>
      <inertia ixx="0.000943493" ixy="3.4393e-05" ixz="-3.8828e-05" iyy="0.000711024" iyz="2.3429e-05" izz="0.000610199"/>
    </inertial>
    <visual>
      <geometry>
        <mesh filename="../meshes/arms/palm_right.dae"/>
      </geometry>
      <origin rpy="0.0 0.0 0.0" xyz="0.0 0.0 0.0"/>
    </visual>
    <collision>
      <geometry>
        <mesh filename="../meshes/arms/palm_right.dae"/>
      </geometry>
      <origin rpy="0 0 0" xyz="0 0 0"/>
    </collision>
  </link>
  <gazebo reference="rightPalm">
    <kp>1e5</kp>
    <kd>1</kd>
    <maxVel>0.1</maxVel>
    <minDepth>0.0015</minDepth>
  </gazebo>
  <link name="rightThumbRollLink">
    <inertial>
      <mass value="0.017"/>
      <origin rpy="0 0 0" xyz="0 -0.0 0.01"/>
      <inertia ixx="2.7778767e-06" ixy="5.6718533e-09" ixz="-9.5523207e-08" iyy="3.5462642e-06" iyz="3.663718e-08" izz="1.3553297e-06"/>
    </inertial>
    <visual>
      <geometry>
        <mesh filename="../meshes/fingers/thumbj1_right.dae"/>
      </geometry>
      <origin rpy="0.0 0.0 0.0" xyz="0.0 0.0 0.0"/>
    </visual>
    <collision>
      <geometry>
        <mesh filename="../meshes/fingers/thumbj1_right.dae"/>
      </geometry>
      <origin rpy="0 0 0" xyz="0 0 0"/>
    </collision>
  </link>
  <gazebo reference="rightThumbRollLink">
    <kp>1e5</kp>
    <kd>1</kd>
    <maxVel>0.1</maxVel>
    <minDepth>0.0015</minDepth>
  </gazebo>
  <link name="rightThumbPitch1Link">
    <inertial>
      <mass value="0.02"/>
      <origin rpy="0 0 0" xyz="0.0 -0.005 0.02"/>
      <inertia ixx="4.239e-06" ixy="0.0" ixz="-0.0" iyy="4.582e-06" iyz="0.0" izz="1.47e-06"/>
    </inertial>
    <visual>
      <geometry>
        <mesh filename="../meshes/fingers/thumbj2_right.dae"/>
      </geometry>
      <origin rpy="0.0 0.0 0.0" xyz="0.0 0.0 0.0"/>
    </visual>
    <collision>
      <geometry>
        <mesh filename="../meshes/fingers/thumbj2_right.dae"/>
      </geometry>
      <origin rpy="0 0 0" xyz="0 0 0"/>
    </collision>
  </link>
  <gazebo reference="rightThumbPitch1Link">
    <kp>1e5</kp>
    <kd>1</kd>
    <maxVel>0.1</maxVel>
    <minDepth>0.0015</minDepth>
  </gazebo>
  <link name="rightThumbPitch2Link">
    <inertial>
      <mass value="0.013"/>
      <origin rpy="0 0 0" xyz="0 -0.004 0.017"/>
      <inertia ixx="1.266e-06" ixy="0.0" ixz="-0.0" iyy="1.503e-06" iyz="-0.0" izz="6.99e-07"/>
    </inertial>
    <visual>
      <geometry>
        <mesh filename="../meshes/fingers/thumbj3_right.dae"/>
      </geometry>
      <origin rpy="0.0 0.0 0.0" xyz="0.0 0.0 0.0"/>
    </visual>
    <collision>
      <geometry>
        <mesh filename="../meshes/fingers/thumbj3_right.dae"/>
      </geometry>
      <origin rpy="0 0 0" xyz="0 0 0"/>
    </collision>
  </link>
  <gazebo reference="rightThumbPitch2Link">
    <kp>1e5</kp>
    <kd>1</kd>
    <maxVel>0.1</maxVel>
    <minDepth>0.0015</minDepth>
  </gazebo>
  <link name="rightThumbPitch3Link">
    <inertial>
      <mass value="0.006"/>
      <origin rpy="0 0 0" xyz="0 -0.004 0.01"/>
      <inertia ixx="3.22e-07" ixy="0.0" ixz="0.0" iyy="4.06e-07" iyz="0.0" izz="2.1e-07"/>
    </inertial>
    <visual>
      <geometry>
        <mesh filename="../meshes/fingers/thumbj4_right.dae"/>
      </geometry>
      <origin rpy="0.0 0.0 0.0" xyz="0.0 0.0 0.0"/>
    </visual>
    <collision>
      <geometry>
        <mesh filename="../meshes/fingers/thumbj4_right.dae"/>
      </geometry>
      <origin rpy="0 0 0" xyz="0 0 0"/>
    </collision>
  </link>
  <gazebo reference="rightThumbPitch3Link">
    <kp>1e5</kp>
    <kd>1</kd>
    <maxVel>0.1</maxVel>
    <minDepth>0.0015</minDepth>
  </gazebo>
  <joint name="rightThumbRoll" type="revolute">
    <origin rpy="0.3491 0.0 0.0" xyz="0.0049 -0.0351 0.0228"/>
    <axis xyz="0 1 0"/>
    <parent link="rightPalm"/>
    <child link="rightThumbRollLink"/>
    <limit effort="10" lower="0.0" upper="2.356" velocity="1"/>
    <controller_gains Kd="0.0" Ki="0.0" Kp="5.0"/>
    <dynamics damping="0.5" friction="0.5"/>
  </joint>
  <gazebo reference="rightThumbRoll">
    <provideFeedback>1</provideFeedback>
    <implicitSpringDamper>1</implicitSpringDamper>
  </gazebo>
  <joint name="rightThumbPitch1" type="revolute">
    <origin rpy="-0.3491 0.0 0.0" xyz="0.0 0.0 0.0229"/>
    <axis xyz="1 0 0"/>
    <parent link="rightThumbRollLink"/>
    <child link="rightThumbPitch1Link"/>
    <limit effort="10" lower="0.0" upper="1.658" velocity="1"/>
    <controller_gains Kd="0.0" Ki="0.0" Kp="5.0"/>
    <dynamics damping="0.5" friction="0.5"/>
  </joint>
  <gazebo reference="rightThumbPitch1">
    <provideFeedback>1</provideFeedback>
    <implicitSpringDamper>1</implicitSpringDamper>
  </gazebo>
  <joint name="rightThumbPitch2" type="revolute">
    <origin rpy="0.0 0.0 0.0" xyz="0.0 -0.0066 0.0375"/>
    <axis xyz="1 0 0"/>
    <parent link="rightThumbPitch1Link"/>
    <child link="rightThumbPitch2Link"/>
    <limit effort="10" lower="0.0" upper="1.92" velocity="1"/>
    <controller_gains Kd="0.0" Ki="0.0" Kp="5.0"/>
    <dynamics damping="0.5" friction="0.5"/>
  </joint>
  <gazebo reference="rightThumbPitch2">
    <provideFeedback>1</provideFeedback>
    <implicitSpringDamper>1</implicitSpringDamper>
  </gazebo>
  <joint name="rightThumbPitch3" type="revolute">
    <origin rpy="0.0 0.0 0.0" xyz="0.0 -0.0049 0.0275"/>
    <axis xyz="1 0 0"/>
    <parent link="rightThumbPitch2Link"/>
    <child link="rightThumbPitch3Link"/>
    <limit effort="10" lower="0.0" upper="1.57" velocity="1"/>
    <controller_gains Kd="0.0" Ki="0.0" Kp="5.0"/>
    <dynamics damping="0.5" friction="0.5"/>
  </joint>
  <gazebo reference="rightThumbPitch3">
    <provideFeedback>1</provideFeedback>
    <implicitSpringDamper>1</implicitSpringDamper>
  </gazebo>
  <link name="rightIndexFingerPitch1Link">
    <inertial>
      <mass value="0.02"/>
      <origin rpy="0 0 0" xyz="0 -0.02 0"/>
      <inertia ixx="4.232e-06" ixy="-6e-08" ixz="-8e-09" iyy="1.215e-06" iyz="-7e-09" izz="3.892e-06"/>
    </inertial>
    <visual>
      <geometry>
        <mesh filename="../meshes/fingers/indexj1_right.dae"/>
      </geometry>
      <origin rpy="0.0 0.0 0.0" xyz="0.0 0.0 0.0"/>
    </visual>
    <collision>
      <geometry>
        <mesh filename="../meshes/fingers/indexj1_right.dae"/>
      </geometry>
      <origin rpy="0 0 0" xyz="0 0 0"/>
    </collision>
  </link>
  <gazebo reference="rightIndexFingerPitch1Link">
    <kp>1e5</kp>
    <kd>1</kd>
    <maxVel>0.1</maxVel>
    <minDepth>0.0015</minDepth>
  </gazebo>
  <link name="rightIndexFingerPitch2Link">
    <inertial>
      <mass value="0.018"/>
      <origin rpy="0 0 0" xyz="0 -0.013 0"/>
      <inertia ixx="1.562e-06" ixy="-1.7e-08" ixz="-1.3e-08" iyy="7.22e-07" iyz="3.1e-08" izz="1.255e-06"/>
    </inertial>
    <visual>
      <geometry>
        <mesh filename="../meshes/fingers/indexj2_right.dae"/>
      </geometry>
      <origin rpy="0.0 0.0 0.0" xyz="0.0 0.0 0.0"/>
    </visual>
    <collision>
      <geometry>
        <mesh filename="../meshes/fingers/indexj2_right.dae"/>
      </geometry>
      <origin rpy="0 0 0" xyz="0 0 0"/>
    </collision>
  </link>
  <gazebo reference="rightIndexFingerPitch2Link">
    <kp>1e5</kp>
    <kd>1</kd>
    <maxVel>0.1</maxVel>
    <minDepth>0.0015</minDepth>
  </gazebo>
  <link name="rightIndexFingerPitch3Link">
    <inertial>
      <mass value="0.01"/>
      <origin rpy="0 0 0" xyz="0 -0.01 0"/>
      <inertia ixx="6.02e-07" ixy="-2.4e-08" ixz="0.0" iyy="2.09e-07" iyz="1.7e-08" izz="5.02e-07"/>
    </inertial>
    <visual>
      <geometry>
        <mesh filename="../meshes/fingers/indexj3_right.dae"/>
      </geometry>
      <origin rpy="0.0 0.0 0.0" xyz="0.0 0.0 0.0"/>
    </visual>
    <collision>
      <geometry>
        <mesh filename="../meshes/fingers/indexj3_right.dae"/>
      </geometry>
      <origin rpy="0 0 0" xyz="0 0 0"/>
    </collision>
  </link>
  <gazebo reference="rightIndexFingerPitch3Link">
    <kp>1e5</kp>
    <kd>1</kd>
    <maxVel>0.1</maxVel>
    <minDepth>0.0015</minDepth>
  </gazebo>
  <joint name="rightIndexFingerPitch1" type="revolute">
    <origin rpy="-0.1745 0.0 0.0" xyz="0.0022 -0.0976 0.0235"/>
    <axis xyz="0 0 1"/>
    <parent link="rightPalm"/>
    <child link="rightIndexFingerPitch1Link"/>
    <limit effort="10" lower="0.0" upper="1.57" velocity="1"/>
    <controller_gains Kd="0.0" Ki="0.0" Kp="5.0"/>
    <dynamics damping="0.5" friction="0.5"/>
  </joint>
  <gazebo reference="rightIndexFingerPitch1">
    <provideFeedback>1</provideFeedback>
    <implicitSpringDamper>1</implicitSpringDamper>
  </gazebo>
  <joint name="rightIndexFingerPitch2" type="revolute">
    <origin rpy="0.0 0.0 0.0" xyz="0.0 -0.0381 0.0"/>
    <axis xyz="0 0 1"/>
    <parent link="rightIndexFingerPitch1Link"/>
    <child link="rightIndexFingerPitch2Link"/>
    <limit effort="10" lower="0.0" upper="1.658" velocity="1"/>
    <controller_gains Kd="0.0" Ki="0.0" Kp="5.0"/>
    <dynamics damping="0.5" friction="0.5"/>
  </joint>
  <gazebo reference="rightIndexFingerPitch2">
    <provideFeedback>1</provideFeedback>
    <implicitSpringDamper>1</implicitSpringDamper>
  </gazebo>
  <joint name="rightIndexFingerPitch3" type="revolute">
    <origin rpy="0.0 0.0 0.0" xyz="0.0 -0.0229 0"/>
    <axis xyz="0 0 1"/>
    <parent link="rightIndexFingerPitch2Link"/>
    <child link="rightIndexFingerPitch3Link"/>
    <limit effort="10" lower="0.0" upper="1.92" velocity="1"/>
    <controller_gains Kd="0.0" Ki="0.0" Kp="5.0"/>
    <dynamics damping="0.5" friction="0.5"/>
  </joint>
  <gazebo reference="rightIndexFingerPitch3">
    <provideFeedback>1</provideFeedback>
    <implicitSpringDamper>1</implicitSpringDamper>
  </gazebo>
  <link name="rightMiddleFingerPitch1Link">
    <inertial>
      <mass value="0.02"/>
      <origin rpy="0 0 0" xyz="0 -0.02 0"/>
      <inertia ixx="5.148e-06" ixy="-4.2e-08" ixz="-1.1e-08" iyy="1.322e-06" iyz="-4e-09" izz="4.592e-06"/>
    </inertial>
    <visual>
      <geometry>
        <mesh filename="../meshes/fingers/middlej1_right.dae"/>
      </geometry>
      <origin rpy="0.0 0.0 0.0" xyz="0.0 0.0 0.0"/>
    </visual>
    <collision>
      <geometry>
        <mesh filename="../meshes/fingers/middlej1_right.dae"/>
      </geometry>
      <origin rpy="0 0 0" xyz="0 0 0"/>
    </collision>
  </link>
  <gazebo reference="rightMiddleFingerPitch1Link">
    <kp>1e5</kp>
    <kd>1</kd>
    <maxVel>0.1</maxVel>
    <minDepth>0.0015</minDepth>
  </gazebo>
  <link name="rightMiddleFingerPitch2Link">
    <inertial>
      <mass value="0.011"/>
      <origin rpy="0 0 0" xyz="0 -0.013 0"/>
      <inertia ixx="1.97e-06" ixy="3.4e-08" ixz="-1.1e-08" iyy="5.54e-07" iyz="-7.8e-08" izz="2.272e-06"/>
    </inertial>
    <visual>
      <geometry>
        <mesh filename="../meshes/fingers/middlej2_right.dae"/>
      </geometry>
      <origin rpy="0.0 0.0 0.0" xyz="0.0 0.0 0.0"/>
    </visual>
    <collision>
      <geometry>
        <mesh filename="../meshes/fingers/middlej2_right.dae"/>
      </geometry>
      <origin rpy="0 0 0" xyz="0 0 0"/>
    </collision>
  </link>
  <gazebo reference="rightMiddleFingerPitch2Link">
    <kp>1e5</kp>
    <kd>1</kd>
    <maxVel>0.1</maxVel>
    <minDepth>0.0015</minDepth>
  </gazebo>
  <link name="rightMiddleFingerPitch3Link">
    <inertial>
      <mass value="0.006"/>
      <origin rpy="0 0 0" xyz="0 -0.01 0"/>
      <inertia ixx="3.96e-07" ixy="-9e-09" ixz="-1e-09" iyy="1.6e-07" iyz="1.6e-08" izz="3.03e-07"/>
    </inertial>
    <visual>
      <geometry>
        <mesh filename="../meshes/fingers/middlej3_right.dae"/>
      </geometry>
      <origin rpy="0.0 0.0 0.0" xyz="0.0 0.0 0.0"/>
    </visual>
    <collision>
      <geometry>
        <mesh filename="../meshes/fingers/middlej3_right.dae"/>
      </geometry>
      <origin rpy="0 0 0" xyz="0 0 0"/>
    </collision>
  </link>
  <gazebo reference="rightMiddleFingerPitch3Link">
    <kp>1e5</kp>
    <kd>1</kd>
    <maxVel>0.1</maxVel>
    <minDepth>0.0015</minDepth>
  </gazebo>
  <joint name="rightMiddleFingerPitch1" type="revolute">
    <origin rpy="0.1222 0.0 0.0" xyz="0.0022 -0.097 -0.0119"/>
    <axis xyz="0 0 1"/>
    <parent link="rightPalm"/>
    <child link="rightMiddleFingerPitch1Link"/>
    <limit effort="10" lower="0.0" upper="1.658" velocity="1"/>
    <controller_gains Kd="0.0" Ki="0.0" Kp="5.0"/>
    <dynamics damping="0.5" friction="0.5"/>
  </joint>
  <gazebo reference="rightMiddleFingerPitch1">
    <provideFeedback>1</provideFeedback>
    <implicitSpringDamper>1</implicitSpringDamper>
  </gazebo>
  <joint name="rightMiddleFingerPitch2" type="revolute">
    <origin rpy="0.0 0.0 0.0" xyz="0.0 -0.0381 0.0"/>
    <axis xyz="0 0 1"/>
    <parent link="rightMiddleFingerPitch1Link"/>
    <child link="rightMiddleFingerPitch2Link"/>
    <limit effort="10" lower="0.0" upper="1.92" velocity="1"/>
    <controller_gains Kd="0.0" Ki="0.0" Kp="5.0"/>
    <dynamics damping="0.5" friction="0.5"/>
  </joint>
  <gazebo reference="rightMiddleFingerPitch2">
    <provideFeedback>1</provideFeedback>
    <implicitSpringDamper>1</implicitSpringDamper>
  </gazebo>
  <joint name="rightMiddleFingerPitch3" type="revolute">
    <origin rpy="0.0 0.0 0.0" xyz="0.0 -0.0229 0.0"/>
    <axis xyz="0 0 1"/>
    <parent link="rightMiddleFingerPitch2Link"/>
    <child link="rightMiddleFingerPitch3Link"/>
    <limit effort="10" lower="0.0" upper="1.57" velocity="1"/>
    <controller_gains Kd="0.0" Ki="0.0" Kp="5.0"/>
    <dynamics damping="0.5" friction="0.5"/>
  </joint>
  <gazebo reference="rightMiddleFingerPitch3">
    <provideFeedback>1</provideFeedback>
    <implicitSpringDamper>1</implicitSpringDamper>
  </gazebo>
  <link name="rightPinkyPitch1Link">
    <inertial>
      <mass value="0.02"/>
      <origin rpy="0 0 0" xyz="0 -0.02 0"/>
      <inertia ixx="5.148e-06" ixy="-4.2e-08" ixz="-1.1e-08" iyy="1.322e-06" iyz="-4e-09" izz="4.592e-06"/>
    </inertial>
    <visual>
      <geometry>
        <mesh filename="../meshes/fingers/pinkyj1_right.dae"/>
      </geometry>
      <origin rpy="0.0 0.0 0.0" xyz="0.0 0.0 0.0"/>
    </visual>
    <collision>
      <geometry>
        <mesh filename="../meshes/fingers/pinkyj1_right.dae"/>
      </geometry>
      <origin rpy="0 0 0" xyz="0 0 0"/>
    </collision>
  </link>
  <gazebo reference="rightPinkyPitch1Link">
    <kp>1e5</kp>
    <kd>1</kd>
    <maxVel>0.1</maxVel>
    <minDepth>0.0015</minDepth>
  </gazebo>
  <link name="rightPinkyPitch2Link">
    <inertial>
      <mass value="0.011"/>
      <origin rpy="0 0 0" xyz="0 -0.013 0"/>
      <inertia ixx="1.97e-06" ixy="3.4e-08" ixz="-1.1e-08" iyy="5.54e-07" iyz="-7.8e-08" izz="2.272e-06"/>
    </inertial>
    <visual>
      <geometry>
        <mesh filename="../meshes/fingers/pinkyj2_right.dae"/>
      </geometry>
      <origin rpy="0.0 0.0 0.0" xyz="0.0 0.0 0.0"/>
    </visual>
    <collision>
      <geometry>
        <mesh filename="../meshes/fingers/pinkyj2_right.dae"/>
      </geometry>
      <origin rpy="0 0 0" xyz="0 0 0"/>
    </collision>
  </link>
  <gazebo reference="rightPinkyPitch2Link">
    <kp>1e5</kp>
    <kd>1</kd>
    <maxVel>0.1</maxVel>
    <minDepth>0.0015</minDepth>
  </gazebo>
  <link name="rightPinkyPitch3Link">
    <inertial>
      <mass value="0.006"/>
      <origin rpy="0 0 0" xyz="0 -0.01 0"/>
      <inertia ixx="3.96e-07" ixy="-9e-09" ixz="-1e-09" iyy="1.6e-07" iyz="1.6e-08" izz="3.03e-07"/>
    </inertial>
    <visual>
      <geometry>
        <mesh filename="../meshes/fingers/pinkyj3_right.dae"/>
      </geometry>
      <origin rpy="0.0 0.0 0.0" xyz="0.0 0.0 0.0"/>
    </visual>
    <collision>
      <geometry>
        <mesh filename="../meshes/fingers/pinkyj3_right.dae"/>
      </geometry>
      <origin rpy="0 0 0" xyz="0 0 0"/>
    </collision>
  </link>
  <gazebo reference="rightPinkyPitch3Link">
    <kp>1e5</kp>
    <kd>1</kd>
    <maxVel>0.1</maxVel>
    <minDepth>0.0015</minDepth>
  </gazebo>
  <joint name="rightPinkyPitch1" type="revolute">
    <origin rpy="0.1222 0.0 0.0" xyz="0.0022 -0.0838 -0.041"/>
    <axis xyz="0 0 1"/>
    <parent link="rightPalm"/>
    <child link="rightPinkyPitch1Link"/>
    <limit effort="10" lower="0.0" upper="1.57" velocity="1"/>
    <controller_gains Kd="0.0" Ki="0.0" Kp="5.0"/>
    <dynamics damping="0.5" friction="0.5"/>
  </joint>
  <gazebo reference="rightPinkyPitch1">
    <provideFeedback>1</provideFeedback>
    <implicitSpringDamper>1</implicitSpringDamper>
  </gazebo>
  <joint name="rightPinkyPitch2" type="revolute">
    <origin rpy="0.0 0.0 0.0" xyz="0.0 -0.0381 0.0"/>
    <axis xyz="0 0 1"/>
    <parent link="rightPinkyPitch1Link"/>
    <child link="rightPinkyPitch2Link"/>
    <limit effort="10" lower="0.0" upper="1.658" velocity="1"/>
    <controller_gains Kd="0.0" Ki="0.0" Kp="5.0"/>
    <dynamics damping="0.5" friction="0.5"/>
  </joint>
  <gazebo reference="rightPinkyPitch2">
    <provideFeedback>1</provideFeedback>
    <implicitSpringDamper>1</implicitSpringDamper>
  </gazebo>
  <joint name="rightPinkyPitch3" type="revolute">
    <origin rpy="0.0 0.0 0.0" xyz="0.0 -0.0229 0.0"/>
    <axis xyz="0 0 1"/>
    <parent link="rightPinkyPitch2Link"/>
    <child link="rightPinkyPitch3Link"/>
    <limit effort="10" lower="0.0" upper="1.92" velocity="1"/>
    <controller_gains Kd="0.0" Ki="0.0" Kp="5.0"/>
    <dynamics damping="0.5" friction="0.5"/>
  </joint>
  <gazebo reference="rightPinkyPitch3">
    <provideFeedback>1</provideFeedback>
    <implicitSpringDamper>1</implicitSpringDamper>
  </gazebo>
  <transmission name="rightForearmYawTransmission">
    <type>transmission_interface/SimpleTransmission</type>
    <joint name="rightForearmYaw">
      <hardwareInterface>EffortJointInterface</hardwareInterface>
    </joint>
    <actuator name="rightForearmYaw">
      <node name="/right_arm/j5"/>
      <mechanicalReduction>1</mechanicalReduction>
      <api name="robot_hardware_interface/TurbodriverAPI"/>
    </actuator>
  </transmission>
  <transmission name="rightIndexFingerMotorPitch1Transmission">
    <type>transmission_interface/SimpleTransmission</type>
    <joint name="rightIndexFingerMotorPitch1">
      <hardwareInterface>EffortJointInterface</hardwareInterface>
    </joint>
    <actuator name="rightIndexFingerMotorPitch1">
      <node name="/right_arm/hand/index"/>
      <mechanicalReduction>1</mechanicalReduction>
      <api name="robot_hardware_interface/TurbodriverAPI"/>
    </actuator>
  </transmission>
  <transmission name="rightMiddleFingerMotorPitch1Transmission">
    <type>transmission_interface/SimpleTransmission</type>
    <joint name="rightMiddleFingerMotorPitch1">
      <hardwareInterface>EffortJointInterface</hardwareInterface>
    </joint>
    <actuator name="rightMiddleFingerMotorPitch1">
      <node name="/right_arm/hand/middle"/>
      <mechanicalReduction>1</mechanicalReduction>
      <api name="robot_hardware_interface/TurbodriverAPI"/>
    </actuator>
  </transmission>
  <transmission name="rightPinkyMotorPitch1Transmission">
    <type>transmission_interface/SimpleTransmission</type>
    <joint name="rightPinkyMotorPitch1">
      <hardwareInterface>EffortJointInterface</hardwareInterface>
    </joint>
    <actuator name="rightPinkyMotorPitch1">
      <node name="/right_arm/hand/pinky"/>
      <mechanicalReduction>1</mechanicalReduction>
      <api name="robot_hardware_interface/TurbodriverAPI"/>
    </actuator>
  </transmission>
  <transmission name="rightThumbMotorRollTransmission">
    <type>transmission_interface/SimpleTransmission</type>
    <joint name="rightThumbMotorRoll">
      <hardwareInterface>EffortJointInterface</hardwareInterface>
    </joint>
    <actuator name="rightThumbMotorRoll">
      <node name="/right_arm/hand/thumb_roll"/>
      <mechanicalReduction>1</mechanicalReduction>
      <api name="robot_hardware_interface/TurbodriverAPI"/>
    </actuator>
  </transmission>
  <transmission name="rightThumbMotorPitch1Transmission">
    <type>transmission_interface/SimpleTransmission</type>
    <joint name="rightThumbMotorPitch1">
      <hardwareInterface>EffortJointInterface</hardwareInterface>
    </joint>
    <actuator name="rightThumbMotorPitch1">
      <node name="/right_arm/hand/thumb_proximal"/>
      <mechanicalReduction>1</mechanicalReduction>
      <api name="robot_hardware_interface/TurbodriverAPI"/>
    </actuator>
  </transmission>
  <transmission name="rightThumbMotorPitch2Transmission">
    <type>transmission_interface/SimpleTransmission</type>
    <joint name="rightThumbMotorPitch2">
      <hardwareInterface>EffortJointInterface</hardwareInterface>
    </joint>
    <actuator name="rightThumbMotorPitch2">
      <node name="/right_arm/hand/thumb_distal"/>
      <mechanicalReduction>1</mechanicalReduction>
      <api name="robot_hardware_interface/TurbodriverAPI"/>
    </actuator>
  </transmission>
  <transmission name="rightWristTransmission">
    <type>robot_transmission_interface/WristPushrodTransmission</type>
    <joint name="rightWristPitch">
      <role>pitch</role>
      <hardwareInterface>EffortJointInterface</hardwareInterface>
    </joint>
    <joint name="rightWristRoll">
      <role>roll</role>
      <hardwareInterface>EffortJointInterface</hardwareInterface>
    </joint>
    <actuator name="rightWristRightActuator">
      <node name="/right_arm/wrist/right_actuator"/>
      <role>bottom</role>
      <mechanicalReduction>1</mechanicalReduction>
      <api name="robot_hardware_interface/TurbodriverAPI_linear_futek"/>
    </actuator>
    <actuator name="rightWristLeftActuator">
      <node name="/right_arm/wrist/left_actuator"/>
      <role>top</role>
      <mechanicalReduction>1</mechanicalReduction>
      <api name="robot_hardware_interface/TurbodriverAPI_linear_futek"/>
    </actuator>
  </transmission>

  <link name="rightThumbTip"/>
  <joint name="rightThumbTipJoint" type="fixed">
    <parent link="rightThumbPitch3Link"/>
    <child link="rightThumbTip"/>
    <origin rpy="0 0 0" xyz="0 0 0.02"/>
  </joint>

  <link name="rightIndexFingerTip"/>
  <joint name="rightIndexFingerTipJoint" type="fixed">
    <parent link="rightIndexFingerPitch3Link"/>
    <child link="rightIndexFingerTip"/>
    <origin rpy="0 0 0" xyz="0 -0.02 0"/>
  </joint>

  <link name="rightMiddleFingerTip"/>
  <joint name="rightMiddleFingerTipJoint" type="fixed">
    <parent link="rightMiddleFingerPitch3Link"/>
    <child link="rightMiddleFingerTip"/>
    <origin rpy="0 0 0" xyz="0 -0.02 0"/>
  </joint>

  <link name="rightPinkyTip"/>
  <joint name="rightPinkyTipJoint" type="fixed">
    <parent link="rightPinkyPitch3Link"/>
    <child link="rightPinkyTip"/>
    <origin rpy="0 0 0" xyz="0 -0.02 0"/>
  </joint>

  <joint name="baseJoint" type="fixed">
    <parent link="base"/>
    <child link="rightPalm"/>
    <origin rpy="0 3.14 0" xyz="0 0 0"/>
  </joint>
</robot>
